2025-06-20 08:25:37 - app.routers.repos - ERROR - Error fetching repositories: (psycopg2.OperationalError) could not translate host name "db" to address: nodename nor servname provided, or not known

(Background on this error at: https://sqlalche.me/e/20/e3q8)
2025-06-20 08:28:00 - app.routers.repos - ERROR - Error fetching repositories: (psycopg2.OperationalError) could not translate host name "db" to address: nodename nor servname provided, or not known

(Background on this error at: https://sqlalche.me/e/20/e3q8)
2025-06-20 08:53:07 - error_handlers - ERROR - Unhandled exception: (psycopg2.OperationalError) could not translate host name "db" to address: nodename nor servname provided, or not known

(Background on this error at: https://sqlalche.me/e/20/e3q8) - http://localhost:8000/ideas/shortlist
Traceback (most recent call last):
  File "/Users/randy/.pyenv/versions/3.11.9/lib/python3.11/site-packages/sqlalchemy/engine/base.py", line 145, in __init__
    self._dbapi_connection = engine.raw_connection()
                             ^^^^^^^^^^^^^^^^^^^^^^^
  File "/Users/randy/.pyenv/versions/3.11.9/lib/python3.11/site-packages/sqlalchemy/engine/base.py", line 3297, in raw_connection
    return self.pool.connect()
           ^^^^^^^^^^^^^^^^^^^
  File "/Users/randy/.pyenv/versions/3.11.9/lib/python3.11/site-packages/sqlalchemy/pool/base.py", line 449, in connect
    return _ConnectionFairy._checkout(self)
           ^^^^^^^^^^^^^^^^^^^^^^^^^^^^^^^^
  File "/Users/randy/.pyenv/versions/3.11.9/lib/python3.11/site-packages/sqlalchemy/pool/base.py", line 1264, in _checkout
    fairy = _ConnectionRecord.checkout(pool)
            ^^^^^^^^^^^^^^^^^^^^^^^^^^^^^^^^
  File "/Users/randy/.pyenv/versions/3.11.9/lib/python3.11/site-packages/sqlalchemy/pool/base.py", line 713, in checkout
    rec = pool._do_get()
          ^^^^^^^^^^^^^^
  File "/Users/randy/.pyenv/versions/3.11.9/lib/python3.11/site-packages/sqlalchemy/pool/impl.py", line 179, in _do_get
    with util.safe_reraise():
  File "/Users/randy/.pyenv/versions/3.11.9/lib/python3.11/site-packages/sqlalchemy/util/langhelpers.py", line 224, in __exit__
    raise exc_value.with_traceback(exc_tb)
  File "/Users/randy/.pyenv/versions/3.11.9/lib/python3.11/site-packages/sqlalchemy/pool/impl.py", line 177, in _do_get
    return self._create_connection()
           ^^^^^^^^^^^^^^^^^^^^^^^^^
  File "/Users/randy/.pyenv/versions/3.11.9/lib/python3.11/site-packages/sqlalchemy/pool/base.py", line 390, in _create_connection
    return _ConnectionRecord(self)
           ^^^^^^^^^^^^^^^^^^^^^^^
  File "/Users/randy/.pyenv/versions/3.11.9/lib/python3.11/site-packages/sqlalchemy/pool/base.py", line 675, in __init__
    self.__connect()
  File "/Users/randy/.pyenv/versions/3.11.9/lib/python3.11/site-packages/sqlalchemy/pool/base.py", line 901, in __connect
    with util.safe_reraise():
  File "/Users/randy/.pyenv/versions/3.11.9/lib/python3.11/site-packages/sqlalchemy/util/langhelpers.py", line 224, in __exit__
    raise exc_value.with_traceback(exc_tb)
  File "/Users/randy/.pyenv/versions/3.11.9/lib/python3.11/site-packages/sqlalchemy/pool/base.py", line 897, in __connect
    self.dbapi_connection = connection = pool._invoke_creator(self)
                                         ^^^^^^^^^^^^^^^^^^^^^^^^^^
  File "/Users/randy/.pyenv/versions/3.11.9/lib/python3.11/site-packages/sqlalchemy/engine/create.py", line 646, in connect
    return dialect.connect(*cargs, **cparams)
           ^^^^^^^^^^^^^^^^^^^^^^^^^^^^^^^^^^
  File "/Users/randy/.pyenv/versions/3.11.9/lib/python3.11/site-packages/sqlalchemy/engine/default.py", line 625, in connect
    return self.loaded_dbapi.connect(*cargs, **cparams)  # type: ignore[no-any-return]  # NOQA: E501
           ^^^^^^^^^^^^^^^^^^^^^^^^^^^^^^^^^^^^^^^^^^^^
  File "/Users/randy/.pyenv/versions/3.11.9/lib/python3.11/site-packages/psycopg2/__init__.py", line 122, in connect
    conn = _connect(dsn, connection_factory=connection_factory, **kwasync)
           ^^^^^^^^^^^^^^^^^^^^^^^^^^^^^^^^^^^^^^^^^^^^^^^^^^^^^^^^^^^^^^^
psycopg2.OperationalError: could not translate host name "db" to address: nodename nor servname provided, or not known


The above exception was the direct cause of the following exception:

Traceback (most recent call last):
  File "/Users/randy/.pyenv/versions/3.11.9/lib/python3.11/site-packages/starlette/middleware/errors.py", line 165, in __call__
    await self.app(scope, receive, _send)
  File "/Users/randy/.pyenv/versions/3.11.9/lib/python3.11/site-packages/starlette/middleware/cors.py", line 93, in __call__
    await self.simple_response(scope, receive, send, request_headers=headers)
  File "/Users/randy/.pyenv/versions/3.11.9/lib/python3.11/site-packages/starlette/middleware/cors.py", line 144, in simple_response
    await self.app(scope, receive, send)
  File "/Users/randy/.pyenv/versions/3.11.9/lib/python3.11/site-packages/starlette/middleware/exceptions.py", line 62, in __call__
    await wrap_app_handling_exceptions(self.app, conn)(scope, receive, send)
  File "/Users/randy/.pyenv/versions/3.11.9/lib/python3.11/site-packages/starlette/_exception_handler.py", line 53, in wrapped_app
    raise exc
  File "/Users/randy/.pyenv/versions/3.11.9/lib/python3.11/site-packages/starlette/_exception_handler.py", line 42, in wrapped_app
    await app(scope, receive, sender)
  File "/Users/randy/.pyenv/versions/3.11.9/lib/python3.11/site-packages/starlette/routing.py", line 714, in __call__
    await self.middleware_stack(scope, receive, send)
  File "/Users/randy/.pyenv/versions/3.11.9/lib/python3.11/site-packages/starlette/routing.py", line 734, in app
    await route.handle(scope, receive, send)
  File "/Users/randy/.pyenv/versions/3.11.9/lib/python3.11/site-packages/starlette/routing.py", line 288, in handle
    await self.app(scope, receive, send)
  File "/Users/randy/.pyenv/versions/3.11.9/lib/python3.11/site-packages/starlette/routing.py", line 76, in app
    await wrap_app_handling_exceptions(app, request)(scope, receive, send)
  File "/Users/randy/.pyenv/versions/3.11.9/lib/python3.11/site-packages/starlette/_exception_handler.py", line 53, in wrapped_app
    raise exc
  File "/Users/randy/.pyenv/versions/3.11.9/lib/python3.11/site-packages/starlette/_exception_handler.py", line 42, in wrapped_app
    await app(scope, receive, sender)
  File "/Users/randy/.pyenv/versions/3.11.9/lib/python3.11/site-packages/starlette/routing.py", line 73, in app
    response = await f(request)
               ^^^^^^^^^^^^^^^^
  File "/Users/randy/.pyenv/versions/3.11.9/lib/python3.11/site-packages/fastapi/routing.py", line 301, in app
    raw_response = await run_endpoint_function(
                   ^^^^^^^^^^^^^^^^^^^^^^^^^^^^
  File "/Users/randy/.pyenv/versions/3.11.9/lib/python3.11/site-packages/fastapi/routing.py", line 214, in run_endpoint_function
    return await run_in_threadpool(dependant.call, **values)
           ^^^^^^^^^^^^^^^^^^^^^^^^^^^^^^^^^^^^^^^^^^^^^^^^^
  File "/Users/randy/.pyenv/versions/3.11.9/lib/python3.11/site-packages/starlette/concurrency.py", line 37, in run_in_threadpool
    return await anyio.to_thread.run_sync(func)
           ^^^^^^^^^^^^^^^^^^^^^^^^^^^^^^^^^^^^
  File "/Users/randy/.pyenv/versions/3.11.9/lib/python3.11/site-packages/anyio/to_thread.py", line 56, in run_sync
    return await get_async_backend().run_sync_in_worker_thread(
           ^^^^^^^^^^^^^^^^^^^^^^^^^^^^^^^^^^^^^^^^^^^^^^^^^^^^
  File "/Users/randy/.pyenv/versions/3.11.9/lib/python3.11/site-packages/anyio/_backends/_asyncio.py", line 2470, in run_sync_in_worker_thread
    return await future
           ^^^^^^^^^^^^
  File "/Users/randy/.pyenv/versions/3.11.9/lib/python3.11/site-packages/anyio/_backends/_asyncio.py", line 967, in run
    result = context.run(func, *args)
             ^^^^^^^^^^^^^^^^^^^^^^^^
  File "/Users/randy/Desktop/Dev/Generator-/backend/app/routers/ideas.py", line 14, in get_shortlisted_ideas
    shortlist = get_shortlist_ideas(db)
                ^^^^^^^^^^^^^^^^^^^^^^^
  File "/Users/randy/Desktop/Dev/Generator-/backend/crud.py", line 142, in get_shortlist_ideas
    return db.query(Shortlist).all()
           ^^^^^^^^^^^^^^^^^^^^^^^^^
  File "/Users/randy/.pyenv/versions/3.11.9/lib/python3.11/site-packages/sqlalchemy/orm/query.py", line 2704, in all
    return self._iter().all()  # type: ignore
           ^^^^^^^^^^^^
  File "/Users/randy/.pyenv/versions/3.11.9/lib/python3.11/site-packages/sqlalchemy/orm/query.py", line 2857, in _iter
    result: Union[ScalarResult[_T], Result[_T]] = self.session.execute(
                                                  ^^^^^^^^^^^^^^^^^^^^^
  File "/Users/randy/.pyenv/versions/3.11.9/lib/python3.11/site-packages/sqlalchemy/orm/session.py", line 2365, in execute
    return self._execute_internal(
           ^^^^^^^^^^^^^^^^^^^^^^^
  File "/Users/randy/.pyenv/versions/3.11.9/lib/python3.11/site-packages/sqlalchemy/orm/session.py", line 2241, in _execute_internal
    conn = self._connection_for_bind(bind)
           ^^^^^^^^^^^^^^^^^^^^^^^^^^^^^^^
  File "/Users/randy/.pyenv/versions/3.11.9/lib/python3.11/site-packages/sqlalchemy/orm/session.py", line 2110, in _connection_for_bind
    return trans._connection_for_bind(engine, execution_options)
           ^^^^^^^^^^^^^^^^^^^^^^^^^^^^^^^^^^^^^^^^^^^^^^^^^^^^^
  File "<string>", line 2, in _connection_for_bind
  File "/Users/randy/.pyenv/versions/3.11.9/lib/python3.11/site-packages/sqlalchemy/orm/state_changes.py", line 139, in _go
    ret_value = fn(self, *arg, **kw)
                ^^^^^^^^^^^^^^^^^^^^
  File "/Users/randy/.pyenv/versions/3.11.9/lib/python3.11/site-packages/sqlalchemy/orm/session.py", line 1189, in _connection_for_bind
    conn = bind.connect()
           ^^^^^^^^^^^^^^
  File "/Users/randy/.pyenv/versions/3.11.9/lib/python3.11/site-packages/sqlalchemy/engine/base.py", line 3273, in connect
    return self._connection_cls(self)
           ^^^^^^^^^^^^^^^^^^^^^^^^^^
  File "/Users/randy/.pyenv/versions/3.11.9/lib/python3.11/site-packages/sqlalchemy/engine/base.py", line 147, in __init__
    Connection._handle_dbapi_exception_noconnection(
  File "/Users/randy/.pyenv/versions/3.11.9/lib/python3.11/site-packages/sqlalchemy/engine/base.py", line 2436, in _handle_dbapi_exception_noconnection
    raise sqlalchemy_exception.with_traceback(exc_info[2]) from e
  File "/Users/randy/.pyenv/versions/3.11.9/lib/python3.11/site-packages/sqlalchemy/engine/base.py", line 145, in __init__
    self._dbapi_connection = engine.raw_connection()
                             ^^^^^^^^^^^^^^^^^^^^^^^
  File "/Users/randy/.pyenv/versions/3.11.9/lib/python3.11/site-packages/sqlalchemy/engine/base.py", line 3297, in raw_connection
    return self.pool.connect()
           ^^^^^^^^^^^^^^^^^^^
  File "/Users/randy/.pyenv/versions/3.11.9/lib/python3.11/site-packages/sqlalchemy/pool/base.py", line 449, in connect
    return _ConnectionFairy._checkout(self)
           ^^^^^^^^^^^^^^^^^^^^^^^^^^^^^^^^
  File "/Users/randy/.pyenv/versions/3.11.9/lib/python3.11/site-packages/sqlalchemy/pool/base.py", line 1264, in _checkout
    fairy = _ConnectionRecord.checkout(pool)
            ^^^^^^^^^^^^^^^^^^^^^^^^^^^^^^^^
  File "/Users/randy/.pyenv/versions/3.11.9/lib/python3.11/site-packages/sqlalchemy/pool/base.py", line 713, in checkout
    rec = pool._do_get()
          ^^^^^^^^^^^^^^
  File "/Users/randy/.pyenv/versions/3.11.9/lib/python3.11/site-packages/sqlalchemy/pool/impl.py", line 179, in _do_get
    with util.safe_reraise():
  File "/Users/randy/.pyenv/versions/3.11.9/lib/python3.11/site-packages/sqlalchemy/util/langhelpers.py", line 224, in __exit__
    raise exc_value.with_traceback(exc_tb)
  File "/Users/randy/.pyenv/versions/3.11.9/lib/python3.11/site-packages/sqlalchemy/pool/impl.py", line 177, in _do_get
    return self._create_connection()
           ^^^^^^^^^^^^^^^^^^^^^^^^^
  File "/Users/randy/.pyenv/versions/3.11.9/lib/python3.11/site-packages/sqlalchemy/pool/base.py", line 390, in _create_connection
    return _ConnectionRecord(self)
           ^^^^^^^^^^^^^^^^^^^^^^^
  File "/Users/randy/.pyenv/versions/3.11.9/lib/python3.11/site-packages/sqlalchemy/pool/base.py", line 675, in __init__
    self.__connect()
  File "/Users/randy/.pyenv/versions/3.11.9/lib/python3.11/site-packages/sqlalchemy/pool/base.py", line 901, in __connect
    with util.safe_reraise():
  File "/Users/randy/.pyenv/versions/3.11.9/lib/python3.11/site-packages/sqlalchemy/util/langhelpers.py", line 224, in __exit__
    raise exc_value.with_traceback(exc_tb)
  File "/Users/randy/.pyenv/versions/3.11.9/lib/python3.11/site-packages/sqlalchemy/pool/base.py", line 897, in __connect
    self.dbapi_connection = connection = pool._invoke_creator(self)
                                         ^^^^^^^^^^^^^^^^^^^^^^^^^^
  File "/Users/randy/.pyenv/versions/3.11.9/lib/python3.11/site-packages/sqlalchemy/engine/create.py", line 646, in connect
    return dialect.connect(*cargs, **cparams)
           ^^^^^^^^^^^^^^^^^^^^^^^^^^^^^^^^^^
  File "/Users/randy/.pyenv/versions/3.11.9/lib/python3.11/site-packages/sqlalchemy/engine/default.py", line 625, in connect
    return self.loaded_dbapi.connect(*cargs, **cparams)  # type: ignore[no-any-return]  # NOQA: E501
           ^^^^^^^^^^^^^^^^^^^^^^^^^^^^^^^^^^^^^^^^^^^^
  File "/Users/randy/.pyenv/versions/3.11.9/lib/python3.11/site-packages/psycopg2/__init__.py", line 122, in connect
    conn = _connect(dsn, connection_factory=connection_factory, **kwasync)
           ^^^^^^^^^^^^^^^^^^^^^^^^^^^^^^^^^^^^^^^^^^^^^^^^^^^^^^^^^^^^^^^
sqlalchemy.exc.OperationalError: (psycopg2.OperationalError) could not translate host name "db" to address: nodename nor servname provided, or not known

(Background on this error at: https://sqlalche.me/e/20/e3q8)
2025-06-20 08:56:35 - error_handlers - ERROR - Unhandled exception: (psycopg2.OperationalError) could not translate host name "db" to address: nodename nor servname provided, or not known

(Background on this error at: https://sqlalche.me/e/20/e3q8) - http://localhost:8000/ideas/shortlist
Traceback (most recent call last):
  File "/Users/randy/.pyenv/versions/3.11.9/lib/python3.11/site-packages/sqlalchemy/engine/base.py", line 145, in __init__
    self._dbapi_connection = engine.raw_connection()
                             ^^^^^^^^^^^^^^^^^^^^^^^
  File "/Users/randy/.pyenv/versions/3.11.9/lib/python3.11/site-packages/sqlalchemy/engine/base.py", line 3297, in raw_connection
    return self.pool.connect()
           ^^^^^^^^^^^^^^^^^^^
  File "/Users/randy/.pyenv/versions/3.11.9/lib/python3.11/site-packages/sqlalchemy/pool/base.py", line 449, in connect
    return _ConnectionFairy._checkout(self)
           ^^^^^^^^^^^^^^^^^^^^^^^^^^^^^^^^
  File "/Users/randy/.pyenv/versions/3.11.9/lib/python3.11/site-packages/sqlalchemy/pool/base.py", line 1264, in _checkout
    fairy = _ConnectionRecord.checkout(pool)
            ^^^^^^^^^^^^^^^^^^^^^^^^^^^^^^^^
  File "/Users/randy/.pyenv/versions/3.11.9/lib/python3.11/site-packages/sqlalchemy/pool/base.py", line 713, in checkout
    rec = pool._do_get()
          ^^^^^^^^^^^^^^
  File "/Users/randy/.pyenv/versions/3.11.9/lib/python3.11/site-packages/sqlalchemy/pool/impl.py", line 179, in _do_get
    with util.safe_reraise():
  File "/Users/randy/.pyenv/versions/3.11.9/lib/python3.11/site-packages/sqlalchemy/util/langhelpers.py", line 224, in __exit__
    raise exc_value.with_traceback(exc_tb)
  File "/Users/randy/.pyenv/versions/3.11.9/lib/python3.11/site-packages/sqlalchemy/pool/impl.py", line 177, in _do_get
    return self._create_connection()
           ^^^^^^^^^^^^^^^^^^^^^^^^^
  File "/Users/randy/.pyenv/versions/3.11.9/lib/python3.11/site-packages/sqlalchemy/pool/base.py", line 390, in _create_connection
    return _ConnectionRecord(self)
           ^^^^^^^^^^^^^^^^^^^^^^^
  File "/Users/randy/.pyenv/versions/3.11.9/lib/python3.11/site-packages/sqlalchemy/pool/base.py", line 675, in __init__
    self.__connect()
  File "/Users/randy/.pyenv/versions/3.11.9/lib/python3.11/site-packages/sqlalchemy/pool/base.py", line 901, in __connect
    with util.safe_reraise():
  File "/Users/randy/.pyenv/versions/3.11.9/lib/python3.11/site-packages/sqlalchemy/util/langhelpers.py", line 224, in __exit__
    raise exc_value.with_traceback(exc_tb)
  File "/Users/randy/.pyenv/versions/3.11.9/lib/python3.11/site-packages/sqlalchemy/pool/base.py", line 897, in __connect
    self.dbapi_connection = connection = pool._invoke_creator(self)
                                         ^^^^^^^^^^^^^^^^^^^^^^^^^^
  File "/Users/randy/.pyenv/versions/3.11.9/lib/python3.11/site-packages/sqlalchemy/engine/create.py", line 646, in connect
    return dialect.connect(*cargs, **cparams)
           ^^^^^^^^^^^^^^^^^^^^^^^^^^^^^^^^^^
  File "/Users/randy/.pyenv/versions/3.11.9/lib/python3.11/site-packages/sqlalchemy/engine/default.py", line 625, in connect
    return self.loaded_dbapi.connect(*cargs, **cparams)  # type: ignore[no-any-return]  # NOQA: E501
           ^^^^^^^^^^^^^^^^^^^^^^^^^^^^^^^^^^^^^^^^^^^^
  File "/Users/randy/.pyenv/versions/3.11.9/lib/python3.11/site-packages/psycopg2/__init__.py", line 122, in connect
    conn = _connect(dsn, connection_factory=connection_factory, **kwasync)
           ^^^^^^^^^^^^^^^^^^^^^^^^^^^^^^^^^^^^^^^^^^^^^^^^^^^^^^^^^^^^^^^
psycopg2.OperationalError: could not translate host name "db" to address: nodename nor servname provided, or not known


The above exception was the direct cause of the following exception:

Traceback (most recent call last):
  File "/Users/randy/.pyenv/versions/3.11.9/lib/python3.11/site-packages/starlette/middleware/errors.py", line 165, in __call__
    await self.app(scope, receive, _send)
  File "/Users/randy/.pyenv/versions/3.11.9/lib/python3.11/site-packages/starlette/middleware/cors.py", line 93, in __call__
    await self.simple_response(scope, receive, send, request_headers=headers)
  File "/Users/randy/.pyenv/versions/3.11.9/lib/python3.11/site-packages/starlette/middleware/cors.py", line 144, in simple_response
    await self.app(scope, receive, send)
  File "/Users/randy/.pyenv/versions/3.11.9/lib/python3.11/site-packages/starlette/middleware/exceptions.py", line 62, in __call__
    await wrap_app_handling_exceptions(self.app, conn)(scope, receive, send)
  File "/Users/randy/.pyenv/versions/3.11.9/lib/python3.11/site-packages/starlette/_exception_handler.py", line 53, in wrapped_app
    raise exc
  File "/Users/randy/.pyenv/versions/3.11.9/lib/python3.11/site-packages/starlette/_exception_handler.py", line 42, in wrapped_app
    await app(scope, receive, sender)
  File "/Users/randy/.pyenv/versions/3.11.9/lib/python3.11/site-packages/starlette/routing.py", line 714, in __call__
    await self.middleware_stack(scope, receive, send)
  File "/Users/randy/.pyenv/versions/3.11.9/lib/python3.11/site-packages/starlette/routing.py", line 734, in app
    await route.handle(scope, receive, send)
  File "/Users/randy/.pyenv/versions/3.11.9/lib/python3.11/site-packages/starlette/routing.py", line 288, in handle
    await self.app(scope, receive, send)
  File "/Users/randy/.pyenv/versions/3.11.9/lib/python3.11/site-packages/starlette/routing.py", line 76, in app
    await wrap_app_handling_exceptions(app, request)(scope, receive, send)
  File "/Users/randy/.pyenv/versions/3.11.9/lib/python3.11/site-packages/starlette/_exception_handler.py", line 53, in wrapped_app
    raise exc
  File "/Users/randy/.pyenv/versions/3.11.9/lib/python3.11/site-packages/starlette/_exception_handler.py", line 42, in wrapped_app
    await app(scope, receive, sender)
  File "/Users/randy/.pyenv/versions/3.11.9/lib/python3.11/site-packages/starlette/routing.py", line 73, in app
    response = await f(request)
               ^^^^^^^^^^^^^^^^
  File "/Users/randy/.pyenv/versions/3.11.9/lib/python3.11/site-packages/fastapi/routing.py", line 301, in app
    raw_response = await run_endpoint_function(
                   ^^^^^^^^^^^^^^^^^^^^^^^^^^^^
  File "/Users/randy/.pyenv/versions/3.11.9/lib/python3.11/site-packages/fastapi/routing.py", line 214, in run_endpoint_function
    return await run_in_threadpool(dependant.call, **values)
           ^^^^^^^^^^^^^^^^^^^^^^^^^^^^^^^^^^^^^^^^^^^^^^^^^
  File "/Users/randy/.pyenv/versions/3.11.9/lib/python3.11/site-packages/starlette/concurrency.py", line 37, in run_in_threadpool
    return await anyio.to_thread.run_sync(func)
           ^^^^^^^^^^^^^^^^^^^^^^^^^^^^^^^^^^^^
  File "/Users/randy/.pyenv/versions/3.11.9/lib/python3.11/site-packages/anyio/to_thread.py", line 56, in run_sync
    return await get_async_backend().run_sync_in_worker_thread(
           ^^^^^^^^^^^^^^^^^^^^^^^^^^^^^^^^^^^^^^^^^^^^^^^^^^^^
  File "/Users/randy/.pyenv/versions/3.11.9/lib/python3.11/site-packages/anyio/_backends/_asyncio.py", line 2470, in run_sync_in_worker_thread
    return await future
           ^^^^^^^^^^^^
  File "/Users/randy/.pyenv/versions/3.11.9/lib/python3.11/site-packages/anyio/_backends/_asyncio.py", line 967, in run
    result = context.run(func, *args)
             ^^^^^^^^^^^^^^^^^^^^^^^^
  File "/Users/randy/Desktop/Dev/Generator-/backend/app/routers/ideas.py", line 14, in get_shortlisted_ideas
    shortlist = get_shortlist_ideas(db)
                ^^^^^^^^^^^^^^^^^^^^^^^
  File "/Users/randy/Desktop/Dev/Generator-/backend/crud.py", line 142, in get_shortlist_ideas
    return db.query(Shortlist).all()
           ^^^^^^^^^^^^^^^^^^^^^^^^^
  File "/Users/randy/.pyenv/versions/3.11.9/lib/python3.11/site-packages/sqlalchemy/orm/query.py", line 2704, in all
    return self._iter().all()  # type: ignore
           ^^^^^^^^^^^^
  File "/Users/randy/.pyenv/versions/3.11.9/lib/python3.11/site-packages/sqlalchemy/orm/query.py", line 2857, in _iter
    result: Union[ScalarResult[_T], Result[_T]] = self.session.execute(
                                                  ^^^^^^^^^^^^^^^^^^^^^
  File "/Users/randy/.pyenv/versions/3.11.9/lib/python3.11/site-packages/sqlalchemy/orm/session.py", line 2365, in execute
    return self._execute_internal(
           ^^^^^^^^^^^^^^^^^^^^^^^
  File "/Users/randy/.pyenv/versions/3.11.9/lib/python3.11/site-packages/sqlalchemy/orm/session.py", line 2241, in _execute_internal
    conn = self._connection_for_bind(bind)
           ^^^^^^^^^^^^^^^^^^^^^^^^^^^^^^^
  File "/Users/randy/.pyenv/versions/3.11.9/lib/python3.11/site-packages/sqlalchemy/orm/session.py", line 2110, in _connection_for_bind
    return trans._connection_for_bind(engine, execution_options)
           ^^^^^^^^^^^^^^^^^^^^^^^^^^^^^^^^^^^^^^^^^^^^^^^^^^^^^
  File "<string>", line 2, in _connection_for_bind
  File "/Users/randy/.pyenv/versions/3.11.9/lib/python3.11/site-packages/sqlalchemy/orm/state_changes.py", line 139, in _go
    ret_value = fn(self, *arg, **kw)
                ^^^^^^^^^^^^^^^^^^^^
  File "/Users/randy/.pyenv/versions/3.11.9/lib/python3.11/site-packages/sqlalchemy/orm/session.py", line 1189, in _connection_for_bind
    conn = bind.connect()
           ^^^^^^^^^^^^^^
  File "/Users/randy/.pyenv/versions/3.11.9/lib/python3.11/site-packages/sqlalchemy/engine/base.py", line 3273, in connect
    return self._connection_cls(self)
           ^^^^^^^^^^^^^^^^^^^^^^^^^^
  File "/Users/randy/.pyenv/versions/3.11.9/lib/python3.11/site-packages/sqlalchemy/engine/base.py", line 147, in __init__
    Connection._handle_dbapi_exception_noconnection(
  File "/Users/randy/.pyenv/versions/3.11.9/lib/python3.11/site-packages/sqlalchemy/engine/base.py", line 2436, in _handle_dbapi_exception_noconnection
    raise sqlalchemy_exception.with_traceback(exc_info[2]) from e
  File "/Users/randy/.pyenv/versions/3.11.9/lib/python3.11/site-packages/sqlalchemy/engine/base.py", line 145, in __init__
    self._dbapi_connection = engine.raw_connection()
                             ^^^^^^^^^^^^^^^^^^^^^^^
  File "/Users/randy/.pyenv/versions/3.11.9/lib/python3.11/site-packages/sqlalchemy/engine/base.py", line 3297, in raw_connection
    return self.pool.connect()
           ^^^^^^^^^^^^^^^^^^^
  File "/Users/randy/.pyenv/versions/3.11.9/lib/python3.11/site-packages/sqlalchemy/pool/base.py", line 449, in connect
    return _ConnectionFairy._checkout(self)
           ^^^^^^^^^^^^^^^^^^^^^^^^^^^^^^^^
  File "/Users/randy/.pyenv/versions/3.11.9/lib/python3.11/site-packages/sqlalchemy/pool/base.py", line 1264, in _checkout
    fairy = _ConnectionRecord.checkout(pool)
            ^^^^^^^^^^^^^^^^^^^^^^^^^^^^^^^^
  File "/Users/randy/.pyenv/versions/3.11.9/lib/python3.11/site-packages/sqlalchemy/pool/base.py", line 713, in checkout
    rec = pool._do_get()
          ^^^^^^^^^^^^^^
  File "/Users/randy/.pyenv/versions/3.11.9/lib/python3.11/site-packages/sqlalchemy/pool/impl.py", line 179, in _do_get
    with util.safe_reraise():
  File "/Users/randy/.pyenv/versions/3.11.9/lib/python3.11/site-packages/sqlalchemy/util/langhelpers.py", line 224, in __exit__
    raise exc_value.with_traceback(exc_tb)
  File "/Users/randy/.pyenv/versions/3.11.9/lib/python3.11/site-packages/sqlalchemy/pool/impl.py", line 177, in _do_get
    return self._create_connection()
           ^^^^^^^^^^^^^^^^^^^^^^^^^
  File "/Users/randy/.pyenv/versions/3.11.9/lib/python3.11/site-packages/sqlalchemy/pool/base.py", line 390, in _create_connection
    return _ConnectionRecord(self)
           ^^^^^^^^^^^^^^^^^^^^^^^
  File "/Users/randy/.pyenv/versions/3.11.9/lib/python3.11/site-packages/sqlalchemy/pool/base.py", line 675, in __init__
    self.__connect()
  File "/Users/randy/.pyenv/versions/3.11.9/lib/python3.11/site-packages/sqlalchemy/pool/base.py", line 901, in __connect
    with util.safe_reraise():
  File "/Users/randy/.pyenv/versions/3.11.9/lib/python3.11/site-packages/sqlalchemy/util/langhelpers.py", line 224, in __exit__
    raise exc_value.with_traceback(exc_tb)
  File "/Users/randy/.pyenv/versions/3.11.9/lib/python3.11/site-packages/sqlalchemy/pool/base.py", line 897, in __connect
    self.dbapi_connection = connection = pool._invoke_creator(self)
                                         ^^^^^^^^^^^^^^^^^^^^^^^^^^
  File "/Users/randy/.pyenv/versions/3.11.9/lib/python3.11/site-packages/sqlalchemy/engine/create.py", line 646, in connect
    return dialect.connect(*cargs, **cparams)
           ^^^^^^^^^^^^^^^^^^^^^^^^^^^^^^^^^^
  File "/Users/randy/.pyenv/versions/3.11.9/lib/python3.11/site-packages/sqlalchemy/engine/default.py", line 625, in connect
    return self.loaded_dbapi.connect(*cargs, **cparams)  # type: ignore[no-any-return]  # NOQA: E501
           ^^^^^^^^^^^^^^^^^^^^^^^^^^^^^^^^^^^^^^^^^^^^
  File "/Users/randy/.pyenv/versions/3.11.9/lib/python3.11/site-packages/psycopg2/__init__.py", line 122, in connect
    conn = _connect(dsn, connection_factory=connection_factory, **kwasync)
           ^^^^^^^^^^^^^^^^^^^^^^^^^^^^^^^^^^^^^^^^^^^^^^^^^^^^^^^^^^^^^^^
sqlalchemy.exc.OperationalError: (psycopg2.OperationalError) could not translate host name "db" to address: nodename nor servname provided, or not known

(Background on this error at: https://sqlalche.me/e/20/e3q8)
2025-06-20 08:57:00 - error_handlers - ERROR - Unhandled exception: (psycopg2.OperationalError) could not translate host name "db" to address: nodename nor servname provided, or not known

(Background on this error at: https://sqlalche.me/e/20/e3q8) - http://localhost:8000/ideas/shortlist
Traceback (most recent call last):
  File "/Users/randy/.pyenv/versions/3.11.9/lib/python3.11/site-packages/sqlalchemy/engine/base.py", line 145, in __init__
    self._dbapi_connection = engine.raw_connection()
                             ^^^^^^^^^^^^^^^^^^^^^^^
  File "/Users/randy/.pyenv/versions/3.11.9/lib/python3.11/site-packages/sqlalchemy/engine/base.py", line 3297, in raw_connection
    return self.pool.connect()
           ^^^^^^^^^^^^^^^^^^^
  File "/Users/randy/.pyenv/versions/3.11.9/lib/python3.11/site-packages/sqlalchemy/pool/base.py", line 449, in connect
    return _ConnectionFairy._checkout(self)
           ^^^^^^^^^^^^^^^^^^^^^^^^^^^^^^^^
  File "/Users/randy/.pyenv/versions/3.11.9/lib/python3.11/site-packages/sqlalchemy/pool/base.py", line 1264, in _checkout
    fairy = _ConnectionRecord.checkout(pool)
            ^^^^^^^^^^^^^^^^^^^^^^^^^^^^^^^^
  File "/Users/randy/.pyenv/versions/3.11.9/lib/python3.11/site-packages/sqlalchemy/pool/base.py", line 713, in checkout
    rec = pool._do_get()
          ^^^^^^^^^^^^^^
  File "/Users/randy/.pyenv/versions/3.11.9/lib/python3.11/site-packages/sqlalchemy/pool/impl.py", line 179, in _do_get
    with util.safe_reraise():
  File "/Users/randy/.pyenv/versions/3.11.9/lib/python3.11/site-packages/sqlalchemy/util/langhelpers.py", line 224, in __exit__
    raise exc_value.with_traceback(exc_tb)
  File "/Users/randy/.pyenv/versions/3.11.9/lib/python3.11/site-packages/sqlalchemy/pool/impl.py", line 177, in _do_get
    return self._create_connection()
           ^^^^^^^^^^^^^^^^^^^^^^^^^
  File "/Users/randy/.pyenv/versions/3.11.9/lib/python3.11/site-packages/sqlalchemy/pool/base.py", line 390, in _create_connection
    return _ConnectionRecord(self)
           ^^^^^^^^^^^^^^^^^^^^^^^
  File "/Users/randy/.pyenv/versions/3.11.9/lib/python3.11/site-packages/sqlalchemy/pool/base.py", line 675, in __init__
    self.__connect()
  File "/Users/randy/.pyenv/versions/3.11.9/lib/python3.11/site-packages/sqlalchemy/pool/base.py", line 901, in __connect
    with util.safe_reraise():
  File "/Users/randy/.pyenv/versions/3.11.9/lib/python3.11/site-packages/sqlalchemy/util/langhelpers.py", line 224, in __exit__
    raise exc_value.with_traceback(exc_tb)
  File "/Users/randy/.pyenv/versions/3.11.9/lib/python3.11/site-packages/sqlalchemy/pool/base.py", line 897, in __connect
    self.dbapi_connection = connection = pool._invoke_creator(self)
                                         ^^^^^^^^^^^^^^^^^^^^^^^^^^
  File "/Users/randy/.pyenv/versions/3.11.9/lib/python3.11/site-packages/sqlalchemy/engine/create.py", line 646, in connect
    return dialect.connect(*cargs, **cparams)
           ^^^^^^^^^^^^^^^^^^^^^^^^^^^^^^^^^^
  File "/Users/randy/.pyenv/versions/3.11.9/lib/python3.11/site-packages/sqlalchemy/engine/default.py", line 625, in connect
    return self.loaded_dbapi.connect(*cargs, **cparams)  # type: ignore[no-any-return]  # NOQA: E501
           ^^^^^^^^^^^^^^^^^^^^^^^^^^^^^^^^^^^^^^^^^^^^
  File "/Users/randy/.pyenv/versions/3.11.9/lib/python3.11/site-packages/psycopg2/__init__.py", line 122, in connect
    conn = _connect(dsn, connection_factory=connection_factory, **kwasync)
           ^^^^^^^^^^^^^^^^^^^^^^^^^^^^^^^^^^^^^^^^^^^^^^^^^^^^^^^^^^^^^^^
psycopg2.OperationalError: could not translate host name "db" to address: nodename nor servname provided, or not known


The above exception was the direct cause of the following exception:

Traceback (most recent call last):
  File "/Users/randy/.pyenv/versions/3.11.9/lib/python3.11/site-packages/starlette/middleware/errors.py", line 165, in __call__
    await self.app(scope, receive, _send)
  File "/Users/randy/.pyenv/versions/3.11.9/lib/python3.11/site-packages/starlette/middleware/cors.py", line 93, in __call__
    await self.simple_response(scope, receive, send, request_headers=headers)
  File "/Users/randy/.pyenv/versions/3.11.9/lib/python3.11/site-packages/starlette/middleware/cors.py", line 144, in simple_response
    await self.app(scope, receive, send)
  File "/Users/randy/.pyenv/versions/3.11.9/lib/python3.11/site-packages/starlette/middleware/exceptions.py", line 62, in __call__
    await wrap_app_handling_exceptions(self.app, conn)(scope, receive, send)
  File "/Users/randy/.pyenv/versions/3.11.9/lib/python3.11/site-packages/starlette/_exception_handler.py", line 53, in wrapped_app
    raise exc
  File "/Users/randy/.pyenv/versions/3.11.9/lib/python3.11/site-packages/starlette/_exception_handler.py", line 42, in wrapped_app
    await app(scope, receive, sender)
  File "/Users/randy/.pyenv/versions/3.11.9/lib/python3.11/site-packages/starlette/routing.py", line 714, in __call__
    await self.middleware_stack(scope, receive, send)
  File "/Users/randy/.pyenv/versions/3.11.9/lib/python3.11/site-packages/starlette/routing.py", line 734, in app
    await route.handle(scope, receive, send)
  File "/Users/randy/.pyenv/versions/3.11.9/lib/python3.11/site-packages/starlette/routing.py", line 288, in handle
    await self.app(scope, receive, send)
  File "/Users/randy/.pyenv/versions/3.11.9/lib/python3.11/site-packages/starlette/routing.py", line 76, in app
    await wrap_app_handling_exceptions(app, request)(scope, receive, send)
  File "/Users/randy/.pyenv/versions/3.11.9/lib/python3.11/site-packages/starlette/_exception_handler.py", line 53, in wrapped_app
    raise exc
  File "/Users/randy/.pyenv/versions/3.11.9/lib/python3.11/site-packages/starlette/_exception_handler.py", line 42, in wrapped_app
    await app(scope, receive, sender)
  File "/Users/randy/.pyenv/versions/3.11.9/lib/python3.11/site-packages/starlette/routing.py", line 73, in app
    response = await f(request)
               ^^^^^^^^^^^^^^^^
  File "/Users/randy/.pyenv/versions/3.11.9/lib/python3.11/site-packages/fastapi/routing.py", line 301, in app
    raw_response = await run_endpoint_function(
                   ^^^^^^^^^^^^^^^^^^^^^^^^^^^^
  File "/Users/randy/.pyenv/versions/3.11.9/lib/python3.11/site-packages/fastapi/routing.py", line 214, in run_endpoint_function
    return await run_in_threadpool(dependant.call, **values)
           ^^^^^^^^^^^^^^^^^^^^^^^^^^^^^^^^^^^^^^^^^^^^^^^^^
  File "/Users/randy/.pyenv/versions/3.11.9/lib/python3.11/site-packages/starlette/concurrency.py", line 37, in run_in_threadpool
    return await anyio.to_thread.run_sync(func)
           ^^^^^^^^^^^^^^^^^^^^^^^^^^^^^^^^^^^^
  File "/Users/randy/.pyenv/versions/3.11.9/lib/python3.11/site-packages/anyio/to_thread.py", line 56, in run_sync
    return await get_async_backend().run_sync_in_worker_thread(
           ^^^^^^^^^^^^^^^^^^^^^^^^^^^^^^^^^^^^^^^^^^^^^^^^^^^^
  File "/Users/randy/.pyenv/versions/3.11.9/lib/python3.11/site-packages/anyio/_backends/_asyncio.py", line 2470, in run_sync_in_worker_thread
    return await future
           ^^^^^^^^^^^^
  File "/Users/randy/.pyenv/versions/3.11.9/lib/python3.11/site-packages/anyio/_backends/_asyncio.py", line 967, in run
    result = context.run(func, *args)
             ^^^^^^^^^^^^^^^^^^^^^^^^
  File "/Users/randy/Desktop/Dev/Generator-/backend/app/routers/ideas.py", line 14, in get_shortlisted_ideas
    shortlist = get_shortlist_ideas(db)
                ^^^^^^^^^^^^^^^^^^^^^^^
  File "/Users/randy/Desktop/Dev/Generator-/backend/crud.py", line 142, in get_shortlist_ideas
    return db.query(Shortlist).all()
           ^^^^^^^^^^^^^^^^^^^^^^^^^
  File "/Users/randy/.pyenv/versions/3.11.9/lib/python3.11/site-packages/sqlalchemy/orm/query.py", line 2704, in all
    return self._iter().all()  # type: ignore
           ^^^^^^^^^^^^
  File "/Users/randy/.pyenv/versions/3.11.9/lib/python3.11/site-packages/sqlalchemy/orm/query.py", line 2857, in _iter
    result: Union[ScalarResult[_T], Result[_T]] = self.session.execute(
                                                  ^^^^^^^^^^^^^^^^^^^^^
  File "/Users/randy/.pyenv/versions/3.11.9/lib/python3.11/site-packages/sqlalchemy/orm/session.py", line 2365, in execute
    return self._execute_internal(
           ^^^^^^^^^^^^^^^^^^^^^^^
  File "/Users/randy/.pyenv/versions/3.11.9/lib/python3.11/site-packages/sqlalchemy/orm/session.py", line 2241, in _execute_internal
    conn = self._connection_for_bind(bind)
           ^^^^^^^^^^^^^^^^^^^^^^^^^^^^^^^
  File "/Users/randy/.pyenv/versions/3.11.9/lib/python3.11/site-packages/sqlalchemy/orm/session.py", line 2110, in _connection_for_bind
    return trans._connection_for_bind(engine, execution_options)
           ^^^^^^^^^^^^^^^^^^^^^^^^^^^^^^^^^^^^^^^^^^^^^^^^^^^^^
  File "<string>", line 2, in _connection_for_bind
  File "/Users/randy/.pyenv/versions/3.11.9/lib/python3.11/site-packages/sqlalchemy/orm/state_changes.py", line 139, in _go
    ret_value = fn(self, *arg, **kw)
                ^^^^^^^^^^^^^^^^^^^^
  File "/Users/randy/.pyenv/versions/3.11.9/lib/python3.11/site-packages/sqlalchemy/orm/session.py", line 1189, in _connection_for_bind
    conn = bind.connect()
           ^^^^^^^^^^^^^^
  File "/Users/randy/.pyenv/versions/3.11.9/lib/python3.11/site-packages/sqlalchemy/engine/base.py", line 3273, in connect
    return self._connection_cls(self)
           ^^^^^^^^^^^^^^^^^^^^^^^^^^
  File "/Users/randy/.pyenv/versions/3.11.9/lib/python3.11/site-packages/sqlalchemy/engine/base.py", line 147, in __init__
    Connection._handle_dbapi_exception_noconnection(
  File "/Users/randy/.pyenv/versions/3.11.9/lib/python3.11/site-packages/sqlalchemy/engine/base.py", line 2436, in _handle_dbapi_exception_noconnection
    raise sqlalchemy_exception.with_traceback(exc_info[2]) from e
  File "/Users/randy/.pyenv/versions/3.11.9/lib/python3.11/site-packages/sqlalchemy/engine/base.py", line 145, in __init__
    self._dbapi_connection = engine.raw_connection()
                             ^^^^^^^^^^^^^^^^^^^^^^^
  File "/Users/randy/.pyenv/versions/3.11.9/lib/python3.11/site-packages/sqlalchemy/engine/base.py", line 3297, in raw_connection
    return self.pool.connect()
           ^^^^^^^^^^^^^^^^^^^
  File "/Users/randy/.pyenv/versions/3.11.9/lib/python3.11/site-packages/sqlalchemy/pool/base.py", line 449, in connect
    return _ConnectionFairy._checkout(self)
           ^^^^^^^^^^^^^^^^^^^^^^^^^^^^^^^^
  File "/Users/randy/.pyenv/versions/3.11.9/lib/python3.11/site-packages/sqlalchemy/pool/base.py", line 1264, in _checkout
    fairy = _ConnectionRecord.checkout(pool)
            ^^^^^^^^^^^^^^^^^^^^^^^^^^^^^^^^
  File "/Users/randy/.pyenv/versions/3.11.9/lib/python3.11/site-packages/sqlalchemy/pool/base.py", line 713, in checkout
    rec = pool._do_get()
          ^^^^^^^^^^^^^^
  File "/Users/randy/.pyenv/versions/3.11.9/lib/python3.11/site-packages/sqlalchemy/pool/impl.py", line 179, in _do_get
    with util.safe_reraise():
  File "/Users/randy/.pyenv/versions/3.11.9/lib/python3.11/site-packages/sqlalchemy/util/langhelpers.py", line 224, in __exit__
    raise exc_value.with_traceback(exc_tb)
  File "/Users/randy/.pyenv/versions/3.11.9/lib/python3.11/site-packages/sqlalchemy/pool/impl.py", line 177, in _do_get
    return self._create_connection()
           ^^^^^^^^^^^^^^^^^^^^^^^^^
  File "/Users/randy/.pyenv/versions/3.11.9/lib/python3.11/site-packages/sqlalchemy/pool/base.py", line 390, in _create_connection
    return _ConnectionRecord(self)
           ^^^^^^^^^^^^^^^^^^^^^^^
  File "/Users/randy/.pyenv/versions/3.11.9/lib/python3.11/site-packages/sqlalchemy/pool/base.py", line 675, in __init__
    self.__connect()
  File "/Users/randy/.pyenv/versions/3.11.9/lib/python3.11/site-packages/sqlalchemy/pool/base.py", line 901, in __connect
    with util.safe_reraise():
  File "/Users/randy/.pyenv/versions/3.11.9/lib/python3.11/site-packages/sqlalchemy/util/langhelpers.py", line 224, in __exit__
    raise exc_value.with_traceback(exc_tb)
  File "/Users/randy/.pyenv/versions/3.11.9/lib/python3.11/site-packages/sqlalchemy/pool/base.py", line 897, in __connect
    self.dbapi_connection = connection = pool._invoke_creator(self)
                                         ^^^^^^^^^^^^^^^^^^^^^^^^^^
  File "/Users/randy/.pyenv/versions/3.11.9/lib/python3.11/site-packages/sqlalchemy/engine/create.py", line 646, in connect
    return dialect.connect(*cargs, **cparams)
           ^^^^^^^^^^^^^^^^^^^^^^^^^^^^^^^^^^
  File "/Users/randy/.pyenv/versions/3.11.9/lib/python3.11/site-packages/sqlalchemy/engine/default.py", line 625, in connect
    return self.loaded_dbapi.connect(*cargs, **cparams)  # type: ignore[no-any-return]  # NOQA: E501
           ^^^^^^^^^^^^^^^^^^^^^^^^^^^^^^^^^^^^^^^^^^^^
  File "/Users/randy/.pyenv/versions/3.11.9/lib/python3.11/site-packages/psycopg2/__init__.py", line 122, in connect
    conn = _connect(dsn, connection_factory=connection_factory, **kwasync)
           ^^^^^^^^^^^^^^^^^^^^^^^^^^^^^^^^^^^^^^^^^^^^^^^^^^^^^^^^^^^^^^^
sqlalchemy.exc.OperationalError: (psycopg2.OperationalError) could not translate host name "db" to address: nodename nor servname provided, or not known

(Background on this error at: https://sqlalche.me/e/20/e3q8)
2025-06-20 10:29:47 - app.routers.repos - ERROR - Error fetching repositories: (psycopg2.OperationalError) could not translate host name "db" to address: nodename nor servname provided, or not known

(Background on this error at: https://sqlalche.me/e/20/e3q8)
